<?xml version="1.0" ?>
<robot name="robot_arm_iteration_3" xmlns:xacro="http://www.ros.org/wiki/xacro">

<xacro:include filename="$(find robot_arm_iteration_3_description)/urdf/materials.xacro" />
<xacro:include filename="$(find robot_arm_iteration_3_description)/urdf/robot_arm_iteration_3.trans" />
<xacro:include filename="$(find robot_arm_iteration_3_description)/urdf/robot_arm_iteration_3.gazebo" />
<link name="world" />

<link name="base_link">
  <inertial>
    <origin rpy="0 0 0" xyz="0.007500000209536871 -0.0925000000000005 0.004999999999998648"/>
    <mass value="1.7642874999999998"/>
    <inertia ixx="0.003106" ixy="0.0" ixz="0.0" iyy="0.003547" iyz="0.0" izz="0.006623"/>
  </inertial>
  <visual>
    <origin rpy="0 0 0" xyz="0 0 0"/>
    <geometry>
      <mesh filename="package://robot_arm_iteration_3_description/meshes/base_link.stl" scale="0.001 0.001 0.001"/>
    </geometry>
    <material name="silver"/>
  </visual>
  <collision>
    <origin rpy="0 0 0" xyz="0 0 0"/>
    <geometry>
      <mesh filename="package://robot_arm_iteration_3_description/meshes/base_link.stl" scale="0.001 0.001 0.001"/>
    </geometry>
  </collision>
</link>

<link name="end_effector_1_1">
  <inertial>
    <origin rpy="0 0 0" xyz="-0.08571430453879789 0.08720731856019903 0.0031948207901359993"/>
    <mass value="26.948240250780884"/>
    <inertia ixx="0.13967" ixy="0.013482" ixz="0.000447" iyy="0.076905" iyz="-0.001001" izz="0.166662"/>
  </inertial>
  <visual>
    <origin rpy="0 0 0" xyz="-0.055139 -0.949297 -1.013464"/>
    <geometry>
      <mesh filename="package://robot_arm_iteration_3_description/meshes/end_effector_1_1.stl" scale="0.001 0.001 0.001"/>
    </geometry>
    <material name="silver"/>
  </visual>
  <collision>
    <origin rpy="0 0 0" xyz="-0.055139 -0.949297 -1.013464"/>
    <geometry>
      <mesh filename="package://robot_arm_iteration_3_description/meshes/end_effector_1_1.stl" scale="0.001 0.001 0.001"/>
    </geometry>
  </collision>
</link>

<link name="lnk3_1_1_1">
  <inertial>
    <origin rpy="0 0 0" xyz="-0.03488195277495294 0.26018452863158753 -0.002882210200743529"/>
    <mass value="16.682100082084894"/>
    <inertia ixx="0.79232" ixy="-0.047568" ixz="0.000675" iyy="0.019209" iyz="0.008857" izz="0.799054"/>
  </inertial>
  <visual>
    <origin rpy="0 0 0" xyz="-0.11851 -0.429073 -1.020351"/>
    <geometry>
      <mesh filename="package://robot_arm_iteration_3_description/meshes/lnk3_1_1_1.stl" scale="0.001 0.001 0.001"/>
    </geometry>
    <material name="silver"/>
  </visual>
  <collision>
    <origin rpy="0 0 0" xyz="-0.11851 -0.429073 -1.020351"/>
    <geometry>
      <mesh filename="package://robot_arm_iteration_3_description/meshes/lnk3_1_1_1.stl" scale="0.001 0.001 0.001"/>
    </geometry>
  </collision>
</link>

<link name="lnk2_1_1_1">
  <inertial>
    <origin rpy="0 0 0" xyz="0.06876889930744022 0.2596956511187459 -0.0017133814057339602"/>
    <mass value="16.664861094299134"/>
    <inertia ixx="0.789332" ixy="-0.051795" ixz="0.000137" iyy="0.019516" iyz="0.002107" izz="0.796578"/>
  </inertial>
  <visual>
    <origin rpy="0 0 0" xyz="-0.078576 0.090356 -1.021992"/>
    <geometry>
      <mesh filename="package://robot_arm_iteration_3_description/meshes/lnk2_1_1_1.stl" scale="0.001 0.001 0.001"/>
    </geometry>
    <material name="silver"/>
  </visual>
  <collision>
    <origin rpy="0 0 0" xyz="-0.078576 0.090356 -1.021992"/>
    <geometry>
      <mesh filename="package://robot_arm_iteration_3_description/meshes/lnk2_1_1_1.stl" scale="0.001 0.001 0.001"/>
    </geometry>
  </collision>
</link>

<link name="lnk1_1_1_1">
  <inertial>
    <origin rpy="0 0 0" xyz="0.005281764986251696 0.000530910748004626 0.6166430322444159"/>
    <mass value="19.92746069172297"/>
    <inertia ixx="2.217196" ixy="-0.00017" ixz="-0.041611" iyy="2.220469" iyz="-0.004188" izz="0.013039"/>
  </inertial>
  <visual>
    <origin rpy="0 0 0" xyz="-0.0075 0.0925 -0.01"/>
    <geometry>
      <mesh filename="package://robot_arm_iteration_3_description/meshes/lnk1_1_1_1.stl" scale="0.001 0.001 0.001"/>
    </geometry>
    <material name="silver"/>
  </visual>
  <collision>
    <origin rpy="0 0 0" xyz="-0.0075 0.0925 -0.01"/>
    <geometry>
      <mesh filename="package://robot_arm_iteration_3_description/meshes/lnk1_1_1_1.stl" scale="0.001 0.001 0.001"/>
    </geometry>
  </collision>
</link>

<link name="primatic_limb_v1_1">
  <inertial>
    <origin rpy="0 0 0" xyz="-4.017224986274659e-07 -3.58057296034886e-07 1.2292912021649727e-08"/>
    <mass value="0.5548838024402971"/>
    <inertia ixx="0.000494" ixy="0.0" ixz="0.0" iyy="6.2e-05" iyz="0.0" izz="0.000494"/>
  </inertial>
  <visual>
    <origin rpy="0 0 0" xyz="0.038314 -1.100238 -1.02"/>
    <geometry>
      <mesh filename="package://robot_arm_iteration_3_description/meshes/primatic_limb_v1_1.stl" scale="0.001 0.001 0.001"/>
    </geometry>
    <material name="silver"/>
  </visual>
  <collision>
    <origin rpy="0 0 0" xyz="0.038314 -1.100238 -1.02"/>
    <geometry>
      <mesh filename="package://robot_arm_iteration_3_description/meshes/primatic_limb_v1_1.stl" scale="0.001 0.001 0.001"/>
    </geometry>
  </collision>
</link>

<link name="sensor_module_v1_1">
  <inertial>
    <origin rpy="0 0 0" xyz="-4.0184163538348194e-07 0.00685678479984464 1.2292914020051171e-08"/>
    <mass value="0.17584000000000002"/>
    <inertia ixx="2.9e-05" ixy="-0.0" ixz="0.0" iyy="4.9e-05" iyz="0.0" izz="2.9e-05"/>
  </inertial>
  <visual>
    <origin rpy="0 0 0" xyz="0.038314 -1.150238 -1.02"/>
    <geometry>
      <mesh filename="package://robot_arm_iteration_3_description/meshes/sensor_module_v1_1.stl" scale="0.001 0.001 0.001"/>
    </geometry>
    <material name="silver"/>
  </visual>
  <collision>
    <origin rpy="0 0 0" xyz="0.038314 -1.150238 -1.02"/>
    <geometry>
      <mesh filename="package://robot_arm_iteration_3_description/meshes/sensor_module_v1_1.stl" scale="0.001 0.001 0.001"/>
    </geometry>
  </collision>
</link>

<joint name="Rev10" type="continuous">
  <origin rpy="0 0 0" xyz="-0.063371 0.520224 -0.006887"/>
  <parent link="lnk3_1_1_1"/>
  <child link="end_effector_1_1"/>
  <axis xyz="1.0 0.0 0.0"/>
</joint>

<joint name="Rev11" type="continuous">
  <origin rpy="0 0 0" xyz="0.039934 0.519429 -0.001641"/>
  <parent link="lnk2_1_1_1"/>
  <child link="lnk3_1_1_1"/>
  <axis xyz="1.0 -0.0 0.0"/>
</joint>

<joint name="Rev12" type="continuous">
  <origin rpy="0 0 0" xyz="0.071076 0.002144 1.011992"/>
  <parent link="lnk1_1_1_1"/>
  <child link="lnk2_1_1_1"/>
  <axis xyz="1.0 -0.0 0.0"/>
</joint>

<joint name="Rev13" type="continuous">
  <origin rpy="0 0 0" xyz="0.0075 -0.0925 0.01"/>
  <parent link="base_link"/>
  <child link="lnk1_1_1_1"/>
  <axis xyz="0.0 0.0 1.0"/>
</joint>

<joint name="Slider14" type="prismatic">
  <origin rpy="0 0 0" xyz="-0.093453 0.150941 0.006536"/>
  <parent link="end_effector_1_1"/>
  <child link="primatic_limb_v1_1"/>
  <axis xyz="0.0 -1.0 0.0"/>
  <limit effort="100" lower="-0.1" upper="0.0" velocity="100"/>
</joint>

<joint name="Rev15" type="continuous">
  <origin rpy="0 0 0" xyz="0.0 0.05 0.0"/>
  <parent link="primatic_limb_v1_1"/>
  <child link="sensor_module_v1_1"/>
  <axis xyz="-0.0 1.0 -0.0"/>
</joint>
<joint name="fixedtoground" type="fixed">
  <parent link="world"/>
  <child link="base_link"/>
</joint>
</robot>
